Workbook

Sheet Coverage
A1: Coverage summary (formulas read the Opportunities sheet)
A2: As-of date | B2: 46307
A4: Active rows (action create or update_existing) | B4: =COUNTIFS(Opportunities!$C$2:$C$161,"<>exclude")
A5: Excluded rows | B5: =COUNTIFS(Opportunities!$C$2:$C$161,"exclude")
A6: Total rows | B6: =B4+B5
A7: Active rows with a known deadline | B7: =COUNTIFS(Opportunities!$C$2:$C$161,"<>exclude",Opportunities!$U$2:$U$161,">0")
A8: Closing within 3 days | B8: =COUNTIFS(Opportunities!$C$2:$C$161,"<>exclude",Opportunities!$U$2:$U$161,">="&$B$2,Opportunities!$U$2:$U$161,"<="&$B$2+3)
A9: Closing within 7 days | B9: =COUNTIFS(Opportunities!$C$2:$C$161,"<>exclude",Opportunities!$U$2:$U$161,">="&$B$2,Opportunities!$U$2:$U$161,"<="&$B$2+7)
A10: Closing within 30 days | B10: =COUNTIFS(Opportunities!$C$2:$C$161,"<>exclude",Opportunities!$U$2:$U$161,">="&$B$2,Opportunities!$U$2:$U$161,"<="&$B$2+30)
A11: Leads with no deadline seen | B11: =COUNTIFS(Opportunities!$AT$2:$AT$161,"lead_no_deadline")
A13: Active rows by category and region tier
A14: category | B14: uganda | C14: east_africa | D14: africa | E14: global | F14: total
A15: job | B15: =COUNTIFS(Opportunities!$H$2:$H$161,$A15,Opportunities!$AR$2:$AR$161,B$14,Opportunities!$C$2:$C$161,"<>exclude") | C15: =COUNTIFS(Opportunities!$H$2:$H$161,$A15,Opportunities!$AR$2:$AR$161,C$14,Opportunities!$C$2:$C$161,"<>exclude") | D15: =COUNTIFS(Opportunities!$H$2:$H$161,$A15,Opportunities!$AR$2:$AR$161,D$14,Opportunities!$C$2:$C$161,"<>exclude") | E15: =COUNTIFS(Opportunities!$H$2:$H$161,$A15,Opportunities!$AR$2:$AR$161,E$14,Opportunities!$C$2:$C$161,"<>exclude") | F15: =SUM(B15:E15)
A16: internship | B16: =COUNTIFS(Opportunities!$H$2:$H$161,$A16,Opportunities!$AR$2:$AR$161,B$14,Opportunities!$C$2:$C$161,"<>exclude") | C16: =COUNTIFS(Opportunities!$H$2:$H$161,$A16,Opportunities!$AR$2:$AR$161,C$14,Opportunities!$C$2:$C$161,"<>exclude") | D16: =COUNTIFS(Opportunities!$H$2:$H$161,$A16,Opportunities!$AR$2:$AR$161,D$14,Opportunities!$C$2:$C$161,"<>exclude") | E16: =COUNTIFS(Opportunities!$H$2:$H$161,$A16,Opportunities!$AR$2:$AR$161,E$14,Opportunities!$C$2:$C$161,"<>exclude") | F16: =SUM(B16:E16)
A17: scholarship | B17: =COUNTIFS(Opportunities!$H$2:$H$161,$A17,Opportunities!$AR$2:$AR$161,B$14,Opportunities!$C$2:$C$161,"<>exclude") | C17: =COUNTIFS(Opportunities!$H$2:$H$161,$A17,Opportunities!$AR$2:$AR$161,C$14,Opportunities!$C$2:$C$161,"<>exclude") | D17: =COUNTIFS(Opportunities!$H$2:$H$161,$A17,Opportunities!$AR$2:$AR$161,D$14,Opportunities!$C$2:$C$161,"<>exclude") | E17: =COUNTIFS(Opportunities!$H$2:$H$161,$A17,Opportunities!$AR$2:$AR$161,E$14,Opportunities!$C$2:$C$161,"<>exclude") | F17: =SUM(B17:E17)
A18: fellowship | B18: =COUNTIFS(Opportunities!$H$2:$H$161,$A18,Opportunities!$AR$2:$AR$161,B$14,Opportunities!$C$2:$C$161,"<>exclude") | C18: =COUNTIFS(Opportunities!$H$2:$H$161,$A18,Opportunities!$AR$2:$AR$161,C$14,Opportunities!$C$2:$C$161,"<>exclude") | D18: =COUNTIFS(Opportunities!$H$2:$H$161,$A18,Opportunities!$AR$2:$AR$161,D$14,Opportunities!$C$2:$C$161,"<>exclude") | E18: =COUNTIFS(Opportunities!$H$2:$H$161,$A18,Opportunities!$AR$2:$AR$161,E$14,Opportunities!$C$2:$C$161,"<>exclude") | F18: =SUM(B18:E18)
A19: grant | B19: =COUNTIFS(Opportunities!$H$2:$H$161,$A19,Opportunities!$AR$2:$AR$161,B$14,Opportunities!$C$2:$C$161,"<>exclude") | C19: =COUNTIFS(Opportunities!$H$2:$H$161,$A19,Opportunities!$AR$2:$AR$161,C$14,Opportunities!$C$2:$C$161,"<>exclude") | D19: =COUNTIFS(Opportunities!$H$2:$H$161,$A19,Opportunities!$AR$2:$AR$161,D$14,Opportunities!$C$2:$C$161,"<>exclude") | E19: =COUNTIFS(Opportunities!$H$2:$H$161,$A19,Opportunities!$AR$2:$AR$161,E$14,Opportunities!$C$2:$C$161,"<>exclude") | F19: =SUM(B19:E19)
A20: training | B20: =COUNTIFS(Opportunities!$H$2:$H$161,$A20,Opportunities!$AR$2:$AR$161,B$14,Opportunities!$C$2:$C$161,"<>exclude") | C20: =COUNTIFS(Opportunities!$H$2:$H$161,$A20,Opportunities!$AR$2:$AR$161,C$14,Opportunities!$C$2:$C$161,"<>exclude") | D20: =COUNTIFS(Opportunities!$H$2:$H$161,$A20,Opportunities!$AR$2:$AR$161,D$14,Opportunities!$C$2:$C$161,"<>exclude") | E20: =COUNTIFS(Opportunities!$H$2:$H$161,$A20,Opportunities!$AR$2:$AR$161,E$14,Opportunities!$C$2:$C$161,"<>exclude") | F20: =SUM(B20:E20)
A21: consultancy | B21: =COUNTIFS(Opportunities!$H$2:$H$161,$A21,Opportunities!$AR$2:$AR$161,B$14,Opportunities!$C$2:$C$161,"<>exclude") | C21: =COUNTIFS(Opportunities!$H$2:$H$161,$A21,Opportunities!$AR$2:$AR$161,C$14,Opportunities!$C$2:$C$161,"<>exclude") | D21: =COUNTIFS(Opportunities!$H$2:$H$161,$A21,Opportunities!$AR$2:$AR$161,D$14,Opportunities!$C$2:$C$161,"<>exclude") | E21: =COUNTIFS(Opportunities!$H$2:$H$161,$A21,Opportunities!$AR$2:$AR$161,E$14,Opportunities!$C$2:$C$161,"<>exclude") | F21: =SUM(B21:E21)
A22: total | B22: =SUM(B15:B21) | C22: =SUM(C15:C21) | D22: =SUM(D15:D21) | E22: =SUM(E15:E21) | F22: =SUM(F15:F21)
A24: Cohort notes
A25: Strong this run: Uganda entry-level and graduate-trainee jobs, and Africa-eligible fellowships and grants from a live feed.
A26: Thin: vocational, trades, hospitality and agriculture jobs outside Kampala; Kenya, Tanzania and Rwanda jobs (index pages only); paid apprenticeships; first-hand scholarship pages from official funders.
A27: No row is marked verified. Every active row needs the provider-owned listing found and checked (see Agent_Check_Plan and README.md).

Sheet Opportunities
A1: record_key | B1: existing_opportunity_id | C1: action | D1: title | E1: organization_name | F1: organization_official_url | G1: organization_reference | H1: category | I1: applicant_type | J1: description | K1: eligibility_json | L1: required_skills_json | M1: preferred_skills_json | N1: location | O1: eligible_countries_json | P1: work_mode | Q1: work_mode_evidence | R1: compensation_status | S1: compensation_details | T1: deadline_utc | U1: deadline_date | V1: deadline_original_text | W1: deadline_timezone | X1: deadline_precision | Y1: deadline_type | Z1: application_method | AA1: application_url | AB1: source_url | AC1: additional_source_urls_json | AD1: source_publication_date | AE1: checked_at_utc | AF1: source | AG1: verification_status | AH1: source_authentic | AI1: no_inappropriate_fees | AJ1: no_sensitive_data_ask | AK1: deadline_plausible | AL1: duplicate_checked | AM1: evidence_json | AN1: additional_costs | AO1: unresolved_requirements_json | AP1: review_notes | AQ1: import_ready | AR1: region_tier | AS1: source_family | AT1: lead_status | AU1: agent_verdict | AV1: agent_checked_at_utc | AW1: official_listing_url | AX1: value_score_0_100 | AY1: effort_score_0_100 | AZ1: risk_score_0_100 | BA1: evidence_files
A2: jentroy-software-dev-intern-2026-10 | C2: create | D2: Software Development Intern (Graduate Program) | E2: Jentroy Uganda | H2: internship | I2: individual | J2: Graduate software development internship in Kampala. Applicants email a CV with a GitHub or portfolio link if available, using the subject line Graduate Intern. | K2: {"educationLevels":["bachelors"]} | N2: Kampala, Uganda | R2: unknown | T2: 2026-10-15T14:00:00Z | U2: 46310 | V2: Deadline: 15th October 2026 at 5:00 PM (EAT) | W2: EAT (UTC+3) | X2: datetime | Y2: fixed | Z2: Email CV (plus GitHub or portfolio link) with subject line Graduate Intern; exact address not captured. | AB2: https://theugandanjobline.com/2026/10/software-development-intern-graduate-program-jobs-jentroy-uganda.html | AC2: [] | AD2: 2026-10-05 | AE2: 2026-10-10T12:00:00Z | AF2: scraped | AG2: pending | AH2: =FALSE() | AI2: =FALSE() | AJ2: =FALSE() | AK2: =TRUE() | AL2: =TRUE() | AM2: {"sourceAuthentic":{"urls":["https://theugandanjobline.com/2026/10/software-development-intern-graduate-program-jobs-jentroy-uganda.html"],"rationale":"Seen on The Ugandan Jobline, a third-party or index page. Provider-owned listing not yet located, so authenticity is unconfirmed.","checkedAtUtc":"2026-10-10T12:00:00Z"},"noInappropriateFees":{"urls":["https://theugandanjobline.com/2026/10/software-development-intern-graduate-program-jobs-jentroy-uganda.html"],"rationale":"The summary text retrieved mentions no fee, but the provider page was not reviewed, so this is unconfirmed.","checkedAtUtc":"2026-10-10T12:00:00Z"},"noSensitiveDataAsk":{"urls":["https://theugandanjobline.com/2026/10/software-development-intern-graduate-program-jobs-jentroy-uganda.html"],"rationale":"The retrieved summary asks for no passwords, codes or payments, but full application instructions were not reviewed.","checkedAtUtc":"2026-10-10T12:00:00Z"},"deadlinePlausible":{"urls":["https://theugandanjobline.com/2026/10/software-development-intern-graduate-program-jobs-jentroy-uganda.html"],"rationale":"Source states 'Deadline: 15th October 2026 at 5:00 PM (EAT)', which falls on or after the delivery date 2026-10-12. Not cross-checked against the provider page.","checkedAtUtc":"2026-10-10T12:00:00Z"},"duplicateChecked":{"urls":[],"rationale":"Title compared with all 115 catalog records and every row in this file using the app's bigram rule (threshold 0.85, 3-day window). Closest catalog title: 'Programme Development Manager' at 0.606.","checkedAtUtc":"2026-10-10T12:00:00Z"}} | AO2: ["Locate the provider-owned listing and the official application link","Confirm no application, processing or placement fee on the official page","Confirm no inappropriate sensitive-data request on the official page","Confirm closing date and timezone on the official page","Compensation not stated","Employer official site and email address not captured"] | AP2: Source page structured data lists a bachelor degree requirement. Only shortlisted candidates are contacted. | AQ2: =FALSE() | AR2: uganda | AS2: theugandanjobline.com | AT2: open_with_deadline | AU2: unresolved | AV2: 2026-10-12T09:15:53Z
A3: natgas-graduate-trainee-software-engineer-2026-10 | C3: create | D3: Graduate Trainee, Software Engineer (2 positions) | E3: NATGAS Uganda | H3: job | I3: individual | J3: Two fresh-graduate trainee software engineer positions advertised by NATGAS Uganda. | N3: Uganda (town not confirmed) | R3: unknown | U3: 46325 | V3: Closes 30 Oct | W3: unknown | X3: date | Y3: fixed | Z3: Apply as described on the source listing; the official application route is not yet confirmed. | AB3: https://theugandanjobline.com/2026/10/graduate-trainee-software-engineer-2-fresh-graduate-positions-jobs-natgas-uganda.html | AC3: [] | AE3: 2026-10-10T12:00:00Z | AF3: scraped | AG3: pending | AH3: =FALSE() | AI3: =FALSE() | AJ3: =FALSE() | AK3: =TRUE() | AL3: =TRUE() | AM3: {"sourceAuthentic":{"urls":["https://theugandanjobline.com/2026/10/graduate-trainee-software-engineer-2-fresh-graduate-positions-jobs-natgas-uganda.html"],"rationale":"Seen on The Ugandan Jobline, a third-party or index page. Provider-owned listing not yet located, so authenticity is unconfirmed.","checkedAtUtc":"2026-10-10T12:00:00Z"},"noInappropriateFees":{"urls":["https://theugandanjobline.com/2026/10/graduate-trainee-software-engineer-2-fresh-graduate-positions-jobs-natgas-uganda.html"],"rationale":"The summary text retrieved mentions no fee, but the provider page was not reviewed, so this is unconfirmed.","checkedAtUtc":"2026-10-10T12:00:00Z"},"noSensitiveDataAsk":{"urls":["https://theugandanjobline.com/2026/10/graduate-trainee-software-engineer-2-fresh-graduate-positions-jobs-natgas-uganda.html"],"rationale":"The retrieved summary asks for no passwords, codes or payments, but full application instructions were not reviewed.","checkedAtUtc":"2026-10-10T12:00:00Z"},"deadlinePlausible":{"urls":["https://theugandanjobline.com/2026/10/graduate-trainee-software-engineer-2-fresh-graduate-positions-jobs-natgas-uganda.html"],"rationale":"Source states 'Closes 30 Oct', which falls on or after the delivery date 2026-10-12. Not cross-checked against the provider page.","checkedAtUtc":"2026-10-10T12:00:00Z"},"duplicateChecked":{"urls":[],"rationale":"Title compared with all 115 catalog records and every row in this file using the app's bigram rule (threshold 0.85, 3-day window). Closest catalog title: 'Senior Business Support Associate (Fleet & Training), G7, Kampala' at 0.413.","checkedAtUtc":"2026-10-10T12:00:00Z"}} | AO3: ["Locate the provider-owned listing and the official application link","Confirm no application, processing or placement fee on the official page","Confirm no inappropriate sensitive-data request on the official page","Confirm closing date and timezone on the official page","Duty station, qualifications and pay not captured"] | AP3: Listing page snapshot seen 2026-10-10; some Ugandan Jobline index pages were 1 to 2 weeks old, so reconfirm the deadline on the employer page. | AQ3: =FALSE() | AR3: uganda | AS3: theugandanjobline.com | AT3: open_with_deadline | AU3: unresolved | AV3: 2026-10-12T09:15:53Z
A4: eacop-gis-graduate-trainee-2026-10 | C4: create | D4: GIS Graduate Trainee | E4: East African Crude Oil Pipeline (EACOP) | H4: job | I4: individual | J4: Graduate trainee role in GIS with the East African Crude Oil Pipeline company, tagged no experience required. | N4: Uganda (town not confirmed) | R4: unknown | U4: 46313 | V4: Closes 18 Oct | W4: unknown | X4: date | Y4: fixed | Z4: Apply as described on the source listing; the official application route is not yet confirmed. | AB4: https://theugandanjobline.com/2026/10/gis-graduate-trainee-no-experience-jobs-jobs-east-african-crude-oil-pipeline.html | AC4: [] | AE4: 2026-10-10T12:00:00Z | AF4: scraped | AG4: pending | AH4: =FALSE() | AI4: =FALSE() | AJ4: =FALSE() | AK4: =TRUE() | AL4: =TRUE() | AM4: {"sourceAuthentic":{"urls":["https://theugandanjobline.com/2026/10/gis-graduate-trainee-no-experience-jobs-jobs-east-african-crude-oil-pipeline.html"],"rationale":"Seen on The Ugandan Jobline, a third-party or index page. Provider-owned listing not yet located, so authenticity is unconfirmed.","checkedAtUtc":"2026-10-10T12:00:00Z"},"noInappropriateFees":{"urls":["https://theugandanjobline.com/2026/10/gis-graduate-trainee-no-experience-jobs-jobs-east-african-crude-oil-pipeline.html"],"rationale":"The summary text retrieved mentions no fee, but the provider page was not reviewed, so this is unconfirmed.","checkedAtUtc":"2026-10-10T12:00:00Z"},"noSensitiveDataAsk":{"urls":["https://theugandanjobline.com/2026/10/gis-graduate-trainee-no-experience-jobs-jobs-east-african-crude-oil-pipeline.html"],"rationale":"The retrieved summary asks for no passwords, codes or payments, but full application instructions were not reviewed.","checkedAtUtc":"2026-10-10T12:00:00Z"},"deadlinePlausible":{"urls":["https://theugandanjobline.com/2026/10/gis-graduate-trainee-no-experience-jobs-jobs-east-african-crude-oil-pipeline.html"],"rationale":"Source states 'Closes 18 Oct', which falls on or after the delivery date 2026-10-12. Not cross-checked against the provider page.","checkedAtUtc":"2026-10-10T12:00:00Z"},"duplicateChecked":{"urls":[],"rationale":"Title compared with all 115 catalog records and every row in this file using the app's bigram rule (threshold 0.85, 3-day window). Closest catalog title: 'Brain Awareness Week Grants' at 0.372.","checkedAtUtc":"2026-10-10T12:00:00Z"}} | AO4: ["Locate the provider-owned listing and the official application link","Confirm no application, processing or placement fee on the official page","Confirm no inappropriate sensitive-data request on the official page","Confirm closing date and timezone on the official page","Qualifications, pay and duty station not captured"] | AP4: EACOP is a politically and environmentally contested project; agent should still verify the posting on the official EACOP careers site. Listing page snapshot seen 2026-10-10; some Ugandan Jobline index pages were 1 to 2 weeks old, so reconfirm the deadline on the employer page. | AQ4: =FALSE() | AR4: uganda | AS4: theugandanjobline.com | AT4: open_with_deadline | AU4: unresolved | AV4: 2026-10-12T09:15:53Z
A5: eacop-hr-graduate-trainee-2026-10 | C5: create | D5: Human Resource Graduate Trainee | E5: East African Crude Oil Pipeline (EACOP) | H5: job | I5: individual | J5: Graduate trainee role in human resources with the East African Crude Oil Pipeline company, tagged no experience required and contract. | N5: Uganda (town not confirmed) | R5: unknown | U5: 46313 | V5: Closes 18 Oct | W5: unknown | X5: date | Y5: fixed | Z5: Apply as described on the source listing; the official application route is not yet confirmed. | AB5: https://theugandanjobline.com/2026/10/human-resource-graduate-trainee-no-experience-jobs-jobs-east-african-crude-oil-pipeline.html | AC5: [] | AE5: 2026-10-10T12:00:00Z | AF5: scraped | AG5: pending | AH5: =FALSE() | AI5: =FALSE() | AJ5: =FALSE() | AK5: =TRUE() | AL5: =TRUE() | AM5: {"sourceAuthentic":{"urls":["https://theugandanjobline.com/2026/10/human-resource-graduate-trainee-no-experience-jobs-jobs-east-african-crude-oil-pipeline.html"],"rationale":"Seen on The Ugandan Jobline, a third-party or index page. Provider-owned listing not yet located, so authenticity is unconfirmed.","checkedAtUtc":"2026-10-10T12:00:00Z"},"noInappropriateFees":{"urls":["https://theugandanjobline.com/2026/10/human-resource-graduate-trainee-no-experience-jobs-jobs-east-african-crude-oil-pipeline.html"],"rationale":"The summary text retrieved mentions no fee, but the provider page was not reviewed, so this is unconfirmed.","checkedAtUtc":"2026-10-10T12:00:00Z"},"noSensitiveDataAsk":{"urls":["https://theugandanjobline.com/2026/10/human-resource-graduate-trainee-no-experience-jobs-jobs-east-african-crude-oil-pipeline.html"],"rationale":"The retrieved summary asks for no passwords, codes or payments, but full application instructions were not reviewed.","checkedAtUtc":"2026-10-10T12:00:00Z"},"deadlinePlausible":{"urls":["https://theugandanjobline.com/2026/10/human-resource-graduate-trainee-no-experience-jobs-jobs-east-african-crude-oil-pipeline.html"],"rationale":"Source states 'Closes 18 Oct', which falls on or after the delivery date 2026-10-12. Not cross-checked against the provider page.","checkedAtUtc":"2026-10-10T12:00:00Z"},"duplicateChecked":{"urls":[],"rationale":"Title compared with all 115 catalog records and every row in this file using the app's bigram rule (threshold 0.85, 3-day window). Closest catalog title: 'Hinrich Foundation Trade Research Grants' at 0.5.","checkedAtUtc":"2026-10-10T12:00:00Z"}} | AO5: ["Locate the provider-owned listing and the official application link","Confirm no application, processing or placement fee on the official page","Confirm no inappropriate sensitive-data request on the official page","Confirm closing date and timezone on the official page","Qualifications, pay and duty station not captured"] | AP5: Listing page snapshot seen 2026-10-10; some Ugandan Jobline index pages were 1 to 2 weeks old, so reconfirm the deadline on the employer page. | AQ5: =FALSE() | AR5: uganda | AS5: theugandanjobline.com | AT5: open_with_deadline | AU5: unresolved | AV5: 2026-10-12T09:15:53Z
A6: mayfair-insurance-ict-graduate-trainee-2026-10 | C6: create | D6: Graduate Trainee, ICT | E6: Mayfair Insurance | H6: job | I6: individual | J6: ICT graduate trainee position at Mayfair Insurance. | N6: Uganda (town not confirmed) | R6: unknown | U6: 46307 | V6: Closes 12 Oct | W6: unknown | X6: date | Y6: fixed | Z6: Apply as described on the source listing; the official application route is not yet confirmed. | AB6: https://theugandanjobline.com/2026/10/graduate-trainee-ict-jobs-mayfair-insurance.html | AC6: [] | AE6: 2026-10-10T12:00:00Z | AF6: scraped | AG6: pending | AH6: =FALSE() | AI6: =FALSE() | AJ6: =FALSE() | AK6: =TRUE() | AL6: =TRUE() | AM6: {"sourceAuthentic":{"urls":["https://theugandanjobline.com/2026/10/graduate-trainee-ict-jobs-mayfair-insurance.html"],"rationale":"Seen on The Ugandan Jobline, a third-party or index page. Provider-owned listing not yet located, so authenticity is unconfirmed.","checkedAtUtc":"2026-10-10T12:00:00Z"},"noInappropriateFees":{"urls":["https://theugandanjobline.com/2026/10/graduate-trainee-ict-jobs-mayfair-insurance.html"],"rationale":"The summary text retrieved mentions no fee, but the provider page was not reviewed, so this is unconfirmed.","checkedAtUtc":"2026-10-10T12:00:00Z"},"noSensitiveDataAsk":{"urls":["https://theugandanjobline.com/2026/10/graduate-trainee-ict-jobs-mayfair-insurance.html"],"rationale":"The retrieved summary asks for no passwords, codes or payments, but full application instructions were not reviewed.","checkedAtUtc":"2026-10-10T12:00:00Z"},"deadlinePlausible":{"urls":["https://theugandanjobline.com/2026/10/graduate-trainee-ict-jobs-mayfair-insurance.html"],"rationale":"Source states 'Closes 12 Oct', which falls on or after the delivery date 2026-10-12. Not cross-checked against the provider page.","checkedAtUtc":"2026-10-10T12:00:00Z"},"duplicateChecked":{"urls":[],"rationale":"Title compared with all 115 catalog records and every row in this file using the app's bigram rule (threshold 0.85, 3-day window). Closest catalog title: 'Hinrich Foundation Trade Research Grants' at 0.34.","checkedAtUtc":"2026-10-10T12:00:00Z"}} | AO6: ["Locate the provider-owned listing and the official application link","Confirm no application, processing or placement fee on the official page","Confirm no inappropriate sensitive-data request on the official page","Confirm closing date and timezone on the official page","Qualifications and pay not captured"] | AP6: Closes today (2026-10-12), re-check immediately. Short window at retrieval. Listing page snapshot seen 2026-10-10; some Ugandan Jobline index pages were 1 to 2 weeks old, so reconfirm the deadline on the employer page. | AQ6: =FALSE() | AR6: uganda | AS6: theugandanjobline.com | AT6: open_with_deadline | AU6: unresolved | AV6: 2026-10-12T09:15:53Z
A7: uetcl-esi-graduate-skills-programme-2026-10 | C7: create | D7: UETCL ESI Graduate Skills Development Programme | E7: Uganda Electricity Transmission Company Limited (UETCL) | H7: training | I7: individual | J7: Graduate skills development programme advertised by UETCL, tagged no experience required. | N7: Uganda (town not confirmed) | R7: unknown | U7: 46308 | V7: Closes 13 Oct | W7: unknown | X7: date | Y7: fixed | Z7: Apply as described on the source listing; the official application route is not yet confirmed. | AB7: https://theugandanjobline.com/2026/10/uetcl-esi-graduate-skills-development-programme-no-experience-jobs-jobs-uganda-electricity-transmission-company-limited-uetcl.html | AC7: [] | AE7: 2026-10-10T12:00:00Z | AF7: scraped | AG7: pending | AH7: =FALSE() | AI7: =FALSE() | AJ7: =FALSE() | AK7: =TRUE() | AL7: =TRUE() | AM7: {"sourceAuthentic":{"urls":["https://theugandanjobline.com/2026/10/uetcl-esi-graduate-skills-development-programme-no-experience-jobs-jobs-uganda-electricity-transmission-company-limited-uetcl.html"],"rationale":"Seen on The Ugandan Jobline, a third-party or index page. Provider-owned listing not yet located, so authenticity is unconfirmed.","checkedAtUtc":"2026-10-10T12:00:00Z"},"noInappropriateFees":{"urls":["https://theugandanjobline.com/2026/10/uetcl-esi-graduate-skills-development-programme-no-experience-jobs-jobs-uganda-electricity-transmission-company-limited-uetcl.html"],"rationale":"The summary text retrieved mentions no fee, but the provider page was not reviewed, so this is unconfirmed.","checkedAtUtc":"2026-10-10T12:00:00Z"},"noSensitiveDataAsk":{"urls":["https://theugandanjobline.com/2026/10/uetcl-esi-graduate-skills-development-programme-no-experience-jobs-jobs-uganda-electricity-transmission-company-limited-uetcl.html"],"rationale":"The retrieved summary asks for no passwords, codes or payments, but full application instructions were not reviewed.","checkedAtUtc":"2026-10-10T12:00:00Z"},"deadlinePlausible":{"urls":["https://theugandanjobline.com/2026/10/uetcl-esi-graduate-skills-development-programme-no-experience-jobs-jobs-uganda-electricity-transmission-company-limited-uetcl.html"],"rationale":"Source states 'Closes 13 Oct', which falls on or after the delivery date 2026-10-12. Not cross-checked against the provider page.","checkedAtUtc":"2026-10-10T12:00:00Z"},"duplicateChecked":{"urls":[],"rationale":"Title compared with all 115 catalog records and every row in this file using the app's bigram rule (threshold 0.85, 3-day window). Closest catalog title: 'Programme Development Manager' at 0.571.","checkedAtUtc":"2026-10-10T12:00:00Z"}} | AO7: ["Locate the provider-owned listing and the official application link","Confirm no application, processing or placement fee on the official page","Confirm no inappropriate sensitive-data request on the official page","Confirm closing date and timezone on the official page","Paid or unpaid not stated","Eligibility not captured"] | AP7: Category set to training because it is a skills programme; confirm whether paid. Listing page snapshot seen 2026-10-10; some Ugandan Jobline index pages were 1 to 2 weeks old, so reconfirm the deadline on the employer page. | AQ7: =FALSE() | AR7: uganda | AS7: theugandanjobline.com | AT7: open_with_deadline | AU7: unresolved | AV7: 2026-10-12T09:15:53Z
A8: uetcl-communication-engineer-2026-10 | C8: create | D8: Communication Engineer (Transmission and Access System) | E8: Uganda Electricity Transmission Company Limited (UETCL) | H8: job | I8: individual | J8: Engineering role in transmission and access communications at UETCL. | N8: Uganda (town not confirmed) | R8: unknown | U8: 46316 | V8: Closes 21 Oct | W8: unknown | X8: date | Y8: fixed | Z8: Apply as described on the source listing; the official application route is not yet confirmed. | AB8: https://theugandanjobline.com/2026/10/communication-engineer-transmission-access-system-jobs-uganda-electricity-transmission-company-limited-uetcl.html | AC8: [] | AE8: 2026-10-10T12:00:00Z | AF8: scraped | AG8: pending | AH8: =FALSE() | AI8: =FALSE() | AJ8: =FALSE() | AK8: =TRUE() | AL8: =TRUE() | AM8: {"sourceAuthentic":{"urls":["https://theugandanjobline.com/2026/10/communication-engineer-transmission-access-system-jobs-uganda-electricity-transmission-company-limited-uetcl.html"],"rationale":"Seen on The Ugandan Jobline, a third-party or index page. Provider-owned listing not yet located, so authenticity is unconfirmed.","checkedAtUtc":"2026-10-10T12:00:00Z"},"noInappropriateFees":{"urls":["https://theugandanjobline.com/2026/10/communication-engineer-transmission-access-system-jobs-uganda-electricity-transmission-company-limited-uetcl.html"],"rationale":"The summary text retrieved mentions no fee, but the provider page was not reviewed, so this is unconfirmed.","checkedAtUtc":"2026-10-10T12:00:00Z"},"noSensitiveDataAsk":{"urls":["https://theugandanjobline.com/2026/10/communication-engineer-transmission-access-system-jobs-uganda-electricity-transmission-company-limited-uetcl.html"],"rationale":"The retrieved summary asks for no passwords, codes or payments, but full application instructions were not reviewed.","checkedAtUtc":"2026-10-10T12:00:00Z"},"deadlinePlausible":{"urls":["https://theugandanjobline.com/2026/10/communication-engineer-transmission-access-system-jobs-uganda-electricity-transmission-company-limited-uetcl.html"],"rationale":"Source states 'Closes 21 Oct', which falls on or after the delivery date 2026-10-12. Not cross-checked against the provider page.","checkedAtUtc":"2026-10-10T12:00:00Z"},"duplicateChecked":{"urls":[],"rationale":"Title compared with all 115 catalog records and every row in this file using the app's bigram rule (threshold 0.85, 3-day window). Closest catalog title: 'UNESCO Communication and Information Sector Internship' at 0.556.","checkedAtUtc":"2026-10-10T12:00:00Z"}} | AO8: ["Locate the provider-owned listing and the official application link","Confirm no application, processing or placement fee on the official page","Confirm no inappropriate sensitive-data request on the official page","Confirm closing date and timezone on the official page","Qualifications and pay not captured"] | AP8: Listing page snapshot seen 2026-10-10; some Ugandan Jobline index pages were 1 to 2 weeks old, so reconfirm the deadline on the employer page. | AQ8: =FALSE() | AR8: uganda | AS8: theugandanjobline.com | AT8: open_with_deadline | AU8: unresolved | AV8: 2026-10-12T09:15:53Z
A9: drc-meal-trainee-uganda-2026-10 | C9: create | D9: MEAL Trainee | E9: Danish Refugee Council (DRC) | F9: https://www.drc.ngo/ | H9: job | I9: individual | J9: Monitoring, evaluation, accountability and learning trainee role listed as a fresh-graduate, no-experience job. | N9: Uganda (town not confirmed) | R9: unknown | U9: 46309 | V9: Closes 14 Oct | W9: unknown | X9: date | Y9: fixed | Z9: Apply as described on the source listing; the official application route is not yet confirmed. | AB9: https://theugandanjobline.com/2026/10/meal-trainee-no-experience-jobs-jobs-danish-refugee-council.html | AC9: [] | AE9: 2026-10-10T12:00:00Z | AF9: scraped | AG9: pending | AH9: =FALSE() | AI9: =FALSE() | AJ9: =FALSE() | AK9: =TRUE() | AL9: =TRUE() | AM9: {"sourceAuthentic":{"urls":["https://theugandanjobline.com/2026/10/meal-trainee-no-experience-jobs-jobs-danish-refugee-council.html"],"rationale":"Seen on The Ugandan Jobline, a third-party or index page. Provider-owned listing not yet located, so authenticity is unconfirmed.","checkedAtUtc":"2026-10-10T12:00:00Z"},"noInappropriateFees":{"urls":["https://theugandanjobline.com/2026/10/meal-trainee-no-experience-jobs-jobs-danish-refugee-council.html"],"rationale":"The summary text retrieved mentions no fee, but the provider page was not reviewed, so this is unconfirmed.","checkedAtUtc":"2026-10-10T12:00:00Z"},"noSensitiveDataAsk":{"urls":["https://theugandanjobline.com/2026/10/meal-trainee-no-experience-jobs-jobs-danish-refugee-council.html"],"rationale":"The retrieved summary asks for no passwords, codes or payments, but full application instructions were not reviewed.","checkedAtUtc":"2026-10-10T12:00:00Z"},"deadlinePlausible":{"urls":["https://theugandanjobline.com/2026/10/meal-trainee-no-experience-jobs-jobs-danish-refugee-council.html"],"rationale":"Source states 'Closes 14 Oct', which falls on or after the delivery date 2026-10-12. Not cross-checked against the provider page.","checkedAtUtc":"2026-10-10T12:00:00Z"},"duplicateChecked":{"urls":[],"rationale":"Title compared with all 115 catalog records and every row in this file using the app's bigram rule (threshold 0.85, 3-day window). Closest catalog title: 'MEAL Officer' at 0.364.","checkedAtUtc":"2026-10-10T12:00:00Z"}} | AO9: ["Locate the provider-owned listing and the official application link","Confirm no application, processing or placement fee on the official page","Confirm no inappropriate sensitive-data request on the official page","Confirm closing date and timezone on the official page","Duty station and contract terms not captured"] | AP9: Check DRC careers portal for the same reference. Listing page snapshot seen 2026-10-10; some Ugandan Jobline index pages were 1 to 2 weeks old, so reconfirm the deadline on the employer page. | AQ9: =FALSE() | AR9: uganda | AS9: theugandanjobline.com | AT9: open_with_deadline | AU9: unresolved | AV9: 2026-10-12T09:15:53Z
A10: naseco-seed-quality-controller-2026-10 | C10: create | D10: Seed Quality Controller (2 positions) | E10: NASECO Seeds | H10: job | I10: individual | J10: Two seed quality controller positions at NASECO Seeds. | N10: Uganda (town not confirmed) | R10: unknown | U10: 46315 | V10: Closes 20 Oct | W10: unknown | X10: date | Y10: fixed | Z10: Apply as described on the source listing; the official application route is not yet confirmed. | AB10: https://theugandanjobline.com/2026/10/seed-quality-controller-2-positions-jobs-naseco-seeds.html | AC10: [] | AE10: 2026-10-10T12:00:00Z | AF10: scraped | AG10: pending | AH10: =FALSE() | AI10: =FALSE() | AJ10: =FALSE() | AK10: =TRUE() | AL10: =TRUE() | AM10: {"sourceAuthentic":{"urls":["https://theugandanjobline.com/2026/10/seed-quality-controller-2-positions-jobs-naseco-seeds.html"],"rationale":"Seen on The Ugandan Jobline, a third-party or index page. Provider-owned listing not yet located, so authenticity is unconfirmed.","checkedAtUtc":"2026-10-10T12:00:00Z"},"noInappropriateFees":{"urls":["https://theugandanjobline.com/2026/10/seed-quality-controller-2-positions-jobs-naseco-seeds.html"],"rationale":"The summary text retrieved mentions no fee, but the provider page was not reviewed, so this is unconfirmed.","checkedAtUtc":"2026-10-10T12:00:00Z"},"noSensitiveDataAsk":{"urls":["https://theugandanjobline.com/2026/10/seed-quality-controller-2-positions-jobs-naseco-seeds.html"],"rationale":"The retrieved summary asks for no passwords, codes or payments, but full application instructions were not reviewed.","checkedAtUtc":"2026-10-10T12:00:00Z"},"deadlinePlausible":{"urls":["https://theugandanjobline.com/2026/10/seed-quality-controller-2-positions-jobs-naseco-seeds.html"],"rationale":"Source states 'Closes 20 Oct', which falls on or after the delivery date 2026-10-12. Not cross-checked against the provider page.","checkedAtUtc":"2026-10-10T12:00:00Z"},"duplicateChecked":{"urls":[],"rationale":"Title compared with all 115 catalog records and every row in this file using the app's bigram rule (threshold 0.85, 3-day window). Closest catalog title: 'Global Poverty and Inequality Innovation Grant' at 0.423.","checkedAtUtc":"2026-10-10T12:00:00Z"}} | AO10: ["Locate the provider-owned listing and the official application link","Confirm no application, processing or placement fee on the official page","Confirm no inappropriate sensitive-data request on the official page","Confirm closing date and timezone on the official page","Qualifications and pay not captured"] | AP10: Listing page snapshot seen 2026-10-10; some Ugandan Jobline index pages were 1 to 2 weeks old, so reconfirm the deadline on the employer page. | AQ10: =FALSE() | AR10: uganda | AS10: theugandanjobline.com | AT10: open_with_deadline | AU10: unresolved | AV10: 2026-10-12T09:15:53Z
A11: naseco-seed-production-lead-2026-10 | C11: create | D11: Production Systems, Early Generation Seed and Variety Advancement Lead | E11: NASECO Seeds | H11: job | I11: individual | J11: Lead role covering production systems, early generation seed and variety advancement at NASECO Seeds. | N11: Uganda (town not confirmed) | R11: unknown | U11: 46315 | V11: Closes 20 Oct | W11: unknown | X11: date | Y11: fixed | Z11: Apply as described on the source listing; the official application route is not yet confirmed. | AB11: https://theugandanjobline.com/2026/10/production-systems-early-generation-seed-and-variety-advancement-lead-jobs-naseco-seeds.html | AC11: [] | AE11: 2026-10-10T12:00:00Z | AF11: scraped | AG11: pending | AH11: =FALSE() | AI11: =FALSE() | AJ11: =FALSE() | AK11: =TRUE() | AL11: =TRUE() | AM11: {"sourceAuthentic":{"urls":["https://theugandanjobline.com/2026/10/production-systems-early-generation-seed-and-variety-advancement-lead-jobs-naseco-seeds.html"],"rationale":"Seen on The Ugandan Jobline, a third-party or index page. Provider-owned listing not yet located, so authenticity is unconfirmed.","checkedAtUtc":"2026-10-10T12:00:00Z"},"noInappropriateFees":{"urls":["https://theugandanjobline.com/2026/10/production-systems-early-generation-seed-and-variety-advancement-lead-jobs-naseco-seeds.html"],"rationale":"The summary text retrieved mentions no fee, but the provider page was not reviewed, so this is unconfirmed.","checkedAtUtc":"2026-10-10T12:00:00Z"},"noSensitiveDataAsk":{"urls":["https://theugandanjobline.com/2026/10/production-systems-early-generation-seed-and-variety-advancement-lead-jobs-naseco-seeds.html"],"rationale":"The retrieved summary asks for no passwords, codes or payments, but full application instructions were not reviewed.","checkedAtUtc":"2026-10-10T12:00:00Z"},"deadlinePlausible":{"urls":["https://theugandanjobline.com/2026/10/production-systems-early-generation-seed-and-variety-advancement-lead-jobs-naseco-seeds.html"],"rationale":"Source states 'Closes 20 Oct', which falls on or after the delivery date 2026-10-12. Not cross-checked against the provider page.","checkedAtUtc":"2026-10-10T12:00:00Z"},"duplicateChecked":{"urls":[],"rationale":"Title compared with all 115 catalog records and every row in this file using the app's bigram rule (threshold 0.85, 3-day window). Closest catalog title: 'Early-Stage Social Enterprises Grant' at 0.465.","checkedAtUtc":"2026-10-10T12:00:00Z"}} | AO11: ["Locate the provider-owned listing and the official application link","Confirm no application, processing or placement fee on the official page","Confirm no inappropriate sensitive-data request on the official page","Confirm closing date and timezone on the official page","Qualifications and pay not captured"] | AP11: Listing page snapshot seen 2026-10-10; some Ugandan Jobline index pages were 1 to 2 weeks old, so reconfirm the deadline on the employer page. | AQ11: =FALSE() | AR11: uganda | AS11: theugandanjobline.com | AT11: open_with_deadline | AU11: unresolved | AV11: 2026-10-12T09:15:53Z
A12: naseco-quality-assurance-supervisor-2026-10 | C12: create | D12: Quality Assurance Supervisor | E12: NASECO Seeds | H12: job | I12: individual | J12: Quality assurance supervisor role at NASECO Seeds. | N12: Uganda (town not confirmed) | R12: unknown | U12: 46315 | V12: Closes 20 Oct | W12: unknown | X12: date | Y12: fixed | Z12: Apply as described on the source listing; the official application route is not yet confirmed. | AB12: https://theugandanjobline.com/2026/10/quality-assurance-supervisor-jobs-naseco-seeds-2.html | AC12: [] | AE12: 2026-10-10T12:00:00Z | AF12: scraped | AG12: pending | AH12: =FALSE() | AI12: =FALSE() | AJ12: =FALSE() | AK12: =TRUE() | AL12: =TRUE() | AM12: {"sourceAuthentic":{"urls":["https://theugandanjobline.com/2026/10/quality-assurance-supervisor-jobs-naseco-seeds-2.html"],"rationale":"Seen on The Ugandan Jobline, a third-party or index page. Provider-owned listing not yet located, so authenticity is unconfirmed.","checkedAtUtc":"2026-10-10T12:00:00Z"},"noInappropriateFees":{"urls":["https://theugandanjobline.com/2026/10/quality-assurance-supervisor-jobs-naseco-seeds-2.html"],"rationale":"The summary text retrieved mentions no fee, but the provider page was not reviewed, so this is unconfirmed.","checkedAtUtc":"2026-10-10T12:00:00Z"},"noSensitiveDataAsk":{"urls":["https://theugandanjobline.com/2026/10/quality-assurance-supervisor-jobs-naseco-seeds-2.html"],"rationale":"The retrieved summary asks for no passwords, codes or payments, but full application instructions were not reviewed.","checkedAtUtc":"2026-10-10T12:00:00Z"},"deadlinePlausible":{"urls":["https://theugandanjobline.com/2026/10/quality-assurance-supervisor-jobs-naseco-seeds-2.html"],"rationale":"Source states 'Closes 20 Oct', which falls on or after the delivery date 2026-10-12. Not cross-checked against the provider page.","checkedAtUtc":"2026-10-10T12:00:00Z"},"duplicateChecked":{"urls":[],"rationale":"Title compared with all 115 catalog records and every row in this file using the app's bigram rule (threshold 0.85, 3-day window). Closest catalog title: 'Grants Finance Senior Associate/Manager' at 0.4.","checkedAtUtc":"2026-10-10T12:00:00Z"}} | AO12: ["Locate the provider-owned listing and the official application link","Confirm no application, processing or placement fee on the official page","Confirm no inappropriate sensitive-data request on the official page","Confirm closing date and timezone on the official page","Qualifications and pay not captured"] | AP12: Listing page snapshot seen 2026-10-10; some Ugandan Jobline index pages were 1 to 2 weeks old, so reconfirm the deadline on the employer page. | AQ12: =FALSE() | AR12: uganda | AS12: theugandanjobline.com | AT12: open_with_deadline | AU12: unresolved | AV12: 2026-10-12T09:15:53Z
A13: giz-uganda-advisor-crrf-maternity-cover-2026-10 | C13: create | D13: Advisor, Comprehensive Refugee Response Framework (maternity cover) | E13: GIZ Uganda | F13: https://www.giz.de/ | H13: job | I13: individual | J13: Advisory role on the Comprehensive Refugee Response Framework with GIZ Uganda, covering a maternity leave. | N13: Uganda (town not confirmed) | R13: unknown | U13: 46318 | V13: Closes 23 Oct | W13: unknown | X13: date | Y13: fixed | Z13: Apply as described on the source listing; the official application route is not yet confirmed. | AB13: https://theugandanjobline.com/2026/10/advisor-maternity-cover-comprehensive-refugee-response-framework-crrf-jobs-giz-uganda.html | AC13: [] | AE13: 2026-10-10T12:00:00Z | AF13: scraped | AG13: pending | AH13: =FALSE() | AI13: =FALSE() | AJ13: =FALSE() | AK13: =TRUE() | AL13: =TRUE() | AM13: {"sourceAuthentic":{"urls":["https://theugandanjobline.com/2026/10/advisor-maternity-cover-comprehensive-refugee-response-framework-crrf-jobs-giz-uganda.html"],"rationale":"Seen on The Ugandan Jobline, a third-party or index page. Provider-owned listing not yet located, so authenticity is unconfirmed.","checkedAtUtc":"2026-10-10T12:00:00Z"},"noInappropriateFees":{"urls":["https://theugandanjobline.com/2026/10/advisor-maternity-cover-comprehensive-refugee-response-framework-crrf-jobs-giz-uganda.html"],"rationale":"The summary text retrieved mentions no fee, but the provider page was not reviewed, so this is unconfirmed.","checkedAtUtc":"2026-10-10T12:00:00Z"},"noSensitiveDataAsk":{"urls":["https://theugandanjobline.com/2026/10/advisor-maternity-cover-comprehensive-refugee-response-framework-crrf-jobs-giz-uganda.html"],"rationale":"The retrieved summary asks for no passwords, codes or payments, but full application instructions were not reviewed.","checkedAtUtc":"2026-10-10T12:00:00Z"},"deadlinePlausible":{"urls":["https://theugandanjobline.com/2026/10/advisor-maternity-cover-comprehensive-refugee-response-framework-crrf-jobs-giz-uganda.html"],"rationale":"Source states 'Closes 23 Oct', which falls on or after the delivery date 2026-10-12. Not cross-checked against the provider page.","checkedAtUtc":"2026-10-10T12:00:00Z"},"duplicateChecked":{"urls":[],"rationale":"Title compared with all 115 catalog records and every row in this file using the app's bigram rule (threshold 0.85, 3-day window). Closest catalog title: 'Territory Field Sales Representative, Mukono' at 0.391.","checkedAtUtc":"2026-10-10T12:00:00Z"}} | AO13: ["Locate the provider-owned listing and the official application link","Confirm no application, processing or placement fee on the official page","Confirm no inappropriate sensitive-data request on the official page","Confirm closing date and timezone on the official page","Contract length and qualifications not captured"] | AP13: Fixed-term cover role. Verify on the GIZ careers portal. Listing page snapshot seen 2026-10-10; some Ugandan Jobline index pages were 1 to 2 weeks old, so reconfirm the deadline on the employer page. | AQ13: =FALSE() | AR13: uganda | AS13: theugandanjobline.com | AT13: open_with_deadline | AU13: unresolved | AV13: 2026-10-12T09:15:53Z
A14: unwomen-uganda-sasa-together-evaluation-2026-10 | C14: create | D14: National Consultant to Evaluate the SASA Together Strategy | E14: UN Women Uganda | F14: https://www.unwomen.org/ | H14: consultancy | I14: individual | J14: National consultancy to evaluate the SASA Together strategy for UN Women in Uganda. | N14: Uganda (town not confirmed) | R14: unknown | U14: 46310 | V14: Closes 15 Oct | W14: unknown | X14: date | Y14: fixed | Z14: Apply as described on the source listing; the official application route is not yet confirmed. | AB14: https://theugandanjobline.com/2026/10/national-consultant-to-evaluate-the-sasa-together-strategy-jobs-unwomen-uganda.html | AC14: [] | AE14: 2026-10-10T12:00:00Z | AF14: scraped | AG14: pending | AH14: =FALSE() | AI14: =FALSE() | AJ14: =FALSE() | AK14: =TRUE() | AL14: =TRUE() | AM14: {"sourceAuthentic":{"urls":["https://theugandanjobline.com/2026/10/national-consultant-to-evaluate-the-sasa-together-strategy-jobs-unwomen-uganda.html"],"rationale":"Seen on The Ugandan Jobline, a third-party or index page. Provider-owned listing not yet located, so authenticity is unconfirmed.","checkedAtUtc":"2026-10-10T12:00:00Z"},"noInappropriateFees":{"urls":["https://theugandanjobline.com/2026/10/national-consultant-to-evaluate-the-sasa-together-strategy-jobs-unwomen-uganda.html"],"rationale":"The summary text retrieved mentions no fee, but the provider page was not reviewed, so this is unconfirmed.","checkedAtUtc":"2026-10-10T12:00:00Z"},"noSensitiveDataAsk":{"urls":["https://theugandanjobline.com/2026/10/national-consultant-to-evaluate-the-sasa-together-strategy-jobs-unwomen-uganda.html"],"rationale":"The retrieved summary asks for no passwords, codes or payments, but full application instructions were not reviewed.","checkedAtUtc":"2026-10-10T12:00:00Z"},"deadlinePlausible":{"urls":["https://theugandanjobline.com/2026/10/national-consultant-to-evaluate-the-sasa-together-strategy-jobs-unwomen-uganda.html"],"rationale":"Source states 'Closes 15 Oct', which falls on or after the delivery date 2026-10-12. Not cross-checked against the provider page.","checkedAtUtc":"2026-10-10T12:00:00Z"},"duplicateChecked":{"urls":[],"rationale":"Title compared with all 115 catalog records and every row in this file using the app's bigram rule (threshold 0.85, 3-day window). Closest catalog title: 'Sensory & Taste Evaluation Specialist' at 0.48.","checkedAtUtc":"2026-10-10T12:00:00Z"}} | AO14: ["Locate the provider-owned listing and the official application link","Confirm no application, processing or placement fee on the official page","Confirm no inappropriate sensitive-data request on the official page","Confirm closing date and timezone on the official page","Nationality restriction, fee and terms of reference not captured"] | AP14: Short window at retrieval. Probably limited to Ugandan nationals (national consultant); confirm. | AQ14: =FALSE() | AR14: uganda | AS14: theugandanjobline.com | AT14: open_with_deadline | AU14: unresolved | AV14: 2026-10-12T09:15:53Z
A15: unicef-uganda-chwp-oversight-consultant-2026-10 | C15: create | D15: National Consultant, Oversight, Coordination, Monitoring and Quality Assurance of the Community Health Workforce Programme | E15: UNICEF Uganda | F15: https://www.unicef.org/uganda/ | H15: consultancy | I15: individual | J15: National consultancy for oversight, coordination, monitoring and quality assurance of the Community Health Workforce Programme. | N15: Uganda (town not confirmed) | R15: unknown | U15: 46310 | V15: Closes 15 Oct | W15: unknown | X15: date | Y15: fixed | Z15: Apply as described on the source listing; the official application route is not yet confirmed. | AB15: https://theugandanjobline.com/2026/10/national-consultant-for-oversight-coordination-monitoring-and-quality-assurance-of-the-community-health-workforce-programme-chwp-jobs-united-nations-childrens-fund.html | AC15: [] | AE15: 2026-10-10T12:00:00Z | AF15: scraped | AG15: pending | AH15: =FALSE() | AI15: =FALSE() | AJ15: =FALSE() | AK15: =TRUE() | AL15: =TRUE() | AM15: {"sourceAuthentic":{"urls":["https://theugandanjobline.com/2026/10/national-consultant-for-oversight-coordination-monitoring-and-quality-assurance-of-the-community-health-workforce-programme-chwp-jobs-united-nations-childrens-fund.html"],"rationale":"Seen on The Ugandan Jobline, a third-party or index page. Provider-owned listing not yet located, so authenticity is unconfirmed.","checkedAtUtc":"2026-10-10T12:00:00Z"},"noInappropriateFees":{"urls":["https://theugandanjobline.com/2026/10/national-consultant-for-oversight-coordination-monitoring-and-quality-assurance-of-the-community-health-workforce-programme-chwp-jobs-united-nations-childrens-fund.html"],"rationale":"The summary text retrieved mentions no fee, but the provider page was not reviewed, so this is unconfirmed.","checkedAtUtc":"2026-10-10T12:00:00Z"},"noSensitiveDataAsk":{"urls":["https://theugandanjobline.com/2026/10/national-consultant-for-oversight-coordination-monitoring-and-quality-assurance-of-the-community-health-workforce-programme-chwp-jobs-united-nations-childrens-fund.html"],"rationale":"The retrieved summary asks for no passwords, codes or payments, but full application instructions were not reviewed.","checkedAtUtc":"2026-10-10T12:00:00Z"},"deadlinePlausible":{"urls":["https://theugandanjobline.com/2026/10/national-consultant-for-oversight-coordination-monitoring-and-quality-assurance-of-the-community-health-workforce-programme-chwp-jobs-united-nations-childrens-fund.html"],"rationale":"Source states 'Closes 15 Oct', which falls on or after the delivery date 2026-10-12. Not cross-checked against the provider page.","checkedAtUtc":"2026-10-10T12:00:00Z"},"duplicateChecked":{"urls":[],"rationale":"Title compared with all 115 catalog records and every row in this file using the app's bigram rule (threshold 0.85, 3-day window). Closest catalog title: 'University of Edinburgh Mastercard Foundation Online Learning Scholars Program' at 0.554.","checkedAtUtc":"2026-10-10T12:00:00Z"}} | AO15: ["Locate the provider-owned listing and the official application link","Confirm no application, processing or placement fee on the official page","Confirm no inappropriate sensitive-data request on the official page","Confirm closing date and timezone on the official page","Nationality restriction and terms of reference not captured"] | AP15: Short window at retrieval. Likely limited to national candidates; confirm on UNICEF careers. | AQ15: =FALSE() | AR15: uganda | AS15: theugandanjobline.com | AT15: open_with_deadline | AU15: unresolved | AV15: 2026-10-12T09:15:53Z
A16: true-north-planning-engineer-offsites-epc-2026-10 | C16: create | D16: Planning Engineer (Offsites and EPC) | E16: True North Consult | H16: job | I16: individual | J16: Planning engineer role for offsites and EPC work at True North Consult. | N16: Uganda (town not confirmed) | R16: unknown | U16: 46307 | V16: Closes 12 Oct | W16: unknown | X16: date | Y16: fixed | Z16: Apply as described on the source listing; the official application route is not yet confirmed. | AB16: https://theugandanjobline.com/2026/10/planning-engineer-offsites-epc-jobs-true-north-consult.html | AC16: [] | AE16: 2026-10-10T12:00:00Z | AF16: scraped | AG16: pending | AH16: =FALSE() | AI16: =FALSE() | AJ16: =FALSE() | AK16: =TRUE() | AL16: =TRUE() | AM16: {"sourceAuthentic":{"urls":["https://theugandanjobline.com/2026/10/planning-engineer-offsites-epc-jobs-true-north-consult.html"],"rationale":"Seen on The Ugandan Jobline, a third-party or index page. Provider-owned listing not yet located, so authenticity is unconfirmed.","checkedAtUtc":"2026-10-10T12:00:00Z"},"noInappropriateFees":{"urls":["https://theugandanjobline.com/2026/10/planning-engineer-offsites-epc-jobs-true-north-consult.html"],"rationale":"The summary text retrieved mentions no fee, but the provider page was not reviewed, so this is unconfirmed.","checkedAtUtc":"2026-10-10T12:00:00Z"},"noSensitiveDataAsk":{"urls":["https://theugandanjobline.com/2026/10/planning-engineer-offsites-epc-jobs-true-north-consult.html"],"rationale":"The retrieved summary asks for no passwords, codes or payments, but full application instructions were not reviewed.","checkedAtUtc":"2026-10-10T12:00:00Z"},"deadlinePlausible":{"urls":["https://theugandanjobline.com/2026/10/planning-engineer-offsites-epc-jobs-true-north-consult.html"],"rationale":"Source states 'Closes 12 Oct', which falls on or after the delivery date 2026-10-12. Not cross-checked against the provider page.","checkedAtUtc":"2026-10-10T12:00:00Z"},"duplicateChecked":{"urls":[],"rationale":"Title compared with all 115 catalog records and every row in this file using the app's bigram rule (threshold 0.85, 3-day window). Closest catalog title: 'Regional Research and Learning Coordinator, PlayMatters' at 0.395.","checkedAtUtc":"2026-10-10T12:00:00Z"}} | AO16: ["Locate the provider-owned listing and the official application link","Confirm no application, processing or placement fee on the official page","Confirm no inappropriate sensitive-data request on the official page","Confirm closing date and timezone on the official page","Qualifications and pay not captured"] | AP16: Closes today (2026-10-12), re-check immediately. Short window at retrieval. Listing page snapshot seen 2026-10-10; some Ugandan Jobline index pages were 1 to 2 weeks old, so reconfirm the deadline on the employer page. | AQ16: =FALSE() | AR16: uganda | AS16: theugandanjobline.com | AT16: open_with_deadline | AU16: unresolved | AV16: 2026-10-12T09:15:53Z
A17: simplepay-internal-debt-collectors-2026-10 | C17: create | D17: Internal Debt Collector (50 positions) | E17: SimplePay Capital | H17: job | I17: individual | J17: Fifty internal debt collector positions at SimplePay Capital. | N17: Uganda (town not confirmed) | R17: unknown | U17: 46335 | V17: Closes 9 Nov | W17: unknown | X17: date | Y17: fixed | Z17: Apply as described on the source listing; the official application route is not yet confirmed. | AB17: https://theugandanjobline.com/2026/10/50-internal-debt-collector-jobs-simplepay-capital.html | AC17: [] | AE17: 2026-10-10T12:00:00Z | AF17: scraped | AG17: pending | AH17: =FALSE() | AI17: =FALSE() | AJ17: =FALSE() | AK17: =TRUE() | AL17: =TRUE() | AM17: {"sourceAuthentic":{"urls":["https://theugandanjobline.com/2026/10/50-internal-debt-collector-jobs-simplepay-capital.html"],"rationale":"Seen on The Ugandan Jobline, a third-party or index page. Provider-owned listing not yet located, so authenticity is unconfirmed.","checkedAtUtc":"2026-10-10T12:00:00Z"},"noInappropriateFees":{"urls":["https://theugandanjobline.com/2026/10/50-internal-debt-collector-jobs-simplepay-capital.html"],"rationale":"The summary text retrieved mentions no fee, but the provider page was not reviewed, so this is unconfirmed.","checkedAtUtc":"2026-10-10T12:00:00Z"},"noSensitiveDataAsk":{"urls":["https://theugandanjobline.com/2026/10/50-internal-debt-collector-jobs-simplepay-capital.html"],"rationale":"The retrieved summary asks for no passwords, codes or payments, but full application instructions were not reviewed.","checkedAtUtc":"2026-10-10T12:00:00Z"},"deadlinePlausible":{"urls":["https://theugandanjobline.com/2026/10/50-internal-debt-collector-jobs-simplepay-capital.html"],"rationale":"Source states 'Closes 9 Nov', which falls on or after the delivery date 2026-10-12. Not cross-checked against the provider page.","checkedAtUtc":"2026-10-10T12:00:00Z"},"duplicateChecked":{"urls":[],"rationale":"Title compared with all 115 catalog records and every row in this file using the app's bigram rule (threshold 0.85, 3-day window). Closest catalog title: 'CSO Call for Expressions of Project Intentions' at 0.5.","checkedAtUtc":"2026-10-10T12:00:00Z"}} | AO17: ["Locate the provider-owned listing and the official application link","Confirm no application, processing or placement fee on the official page","Confirm no inappropriate sensitive-data request on the official page","Confirm closing date and timezone on the official page","Pay structure (salary versus commission) not captured","Lender licence not checked"] | AP17: Mass hiring in lending and collections: agent should check the lender is licensed (Uganda Microfinance Regulatory Authority or Bank of Uganda) and whether pay is commission-only. | AQ17: =FALSE() | AR17: uganda | AS17: theugandanjobline.com | AT17: open_with_deadline | AU17: unresolved | AV17: 2026-10-12T09:15:53Z
A18: tugende-customer-relations-admin-officer-2026-10 | C18: create | D18: Customer Relations and Administration Officer | E18: Tugende | H18: job | I18: individual | J18: Contract customer relations and administration role at Tugende. | N18: Uganda (town not confirmed) | R18: unknown | U18: 46332 | V18: Closes 6 Nov | W18: unknown | X18: date | Y18: fixed | Z18: Apply as described on the source listing; the official application route is not yet confirmed. | AB18: https://theugandanjobline.com/2026/10/customer-relations-and-administration-officer-jobs-tugende.html | AC18: [] | AE18: 2026-10-10T12:00:00Z | AF18: scraped | AG18: pending | AH18: =FALSE() | AI18: =FALSE() | AJ18: =FALSE() | AK18: =TRUE() | AL18: =TRUE() | AM18: {"sourceAuthentic":{"urls":["https://theugandanjobline.com/2026/10/customer-relations-and-administration-officer-jobs-tugende.html"],"rationale":"Seen on The Ugandan Jobline, a third-party or index page. Provider-owned listing not yet located, so authenticity is unconfirmed.","checkedAtUtc":"2026-10-10T12:00:00Z"},"noInappropriateFees":{"urls":["https://theugandanjobline.com/2026/10/customer-relations-and-administration-officer-jobs-tugende.html"],"rationale":"The summary text retrieved mentions no fee, but the provider page was not reviewed, so this is unconfirmed.","checkedAtUtc":"2026-10-10T12:00:00Z"},"noSensitiveDataAsk":{"urls":["https://theugandanjobline.com/2026/10/customer-relations-and-administration-officer-jobs-tugende.html"],"rationale":"The retrieved summary asks for no passwords, codes or payments, but full application instructions were not reviewed.","checkedAtUtc":"2026-10-10T12:00:00Z"},"deadlinePlausible":{"urls":["https://theugandanjobline.com/2026/10/customer-relations-and-administration-officer-jobs-tugende.html"],"rationale":"Source states 'Closes 6 Nov', which falls on or after the delivery date 2026-10-12. Not cross-checked against the provider page.","checkedAtUtc":"2026-10-10T12:00:00Z"},"duplicateChecked":{"urls":[],"rationale":"Title compared with all 115 catalog records and every row in this file using the app's bigram rule (threshold 0.85, 3-day window). Closest catalog title: 'Chief Operations Officer' at 0.483.","checkedAtUtc":"2026-10-10T12:00:00Z"}} | AO18: ["Locate the provider-owned listing and the official application link","Confirm no application, processing or placement fee on the official page","Confirm no inappropriate sensitive-data request on the official page","Confirm closing date and timezone on the official page","Duty station and pay not captured"] | AQ18: =FALSE() | AR18: uganda | AS18: theugandanjobline.com | AT18: open_with_deadline | AU18: unresolved | AV18: 2026-10-12T09:15:53Z
